Workbook
Name EMP_ID: '04_XLOOKUP_Basics'!$B$6:$B$19
Name EMP_NAME: '04_XLOOKUP_Basics'!$C$6:$C$19
Name KPI_MATRIX: '02-HLOOKUP-Basics'!$C$5:$H$12

Sheet 01_Cheatsheet
B1: SYNTAX CHEATSHEET · HLOOKUP vs XLOOKUP vs INDEX/MATCH
B4: FUNCTION SIGNATURES
B5: HLOOKUP
B8: HLOOKUP( lookup_value , table_array , row_index_num , [range_lookup] )
B11: lookup_value | C11: What you are searching for. Usually a cell reference, not a typed literal.
B12: table_array | C12: The whole block. Excel searches ONLY the first row of this block.
B13: row_index_num | C13: 1 = first row of table_array (the headers), 2 = next row, … Fragile if rows are inserted.
B14: range_lookup | C14: FALSE or 0 = exact. TRUE or 1 = approximate (default if omitted). Omitted is the #1 interview trap.
B16: XLOOKUP
B19: XLOOKUP( lookup_value , lookup_array , return_array , [if_not_found] , [match_mode] , [search_mode] )
B22: lookup_value | C22: Same idea. Can be a number, text, date, or a cell. Can also be an array (spills).
B23: lookup_array | C23: ONE row or ONE column — the place you search. Not the whole table.
B24: return_array | C24: ONE row or ONE column (or a 2D block to spill multiple fields). Same size as lookup_array on the search axis.
B25: if_not_found | C25: Optional. Text or value to return instead of #N/A. Prefer this over wrapping IFERROR.
B26: match_mode | C26: 0 exact (default) · −1 exact or next smaller · 1 exact or next larger · 2 wildcard (* ? ~)
B27: search_mode | C27: 1 first-to-last (default) · −1 last-to-first · 2 binary ascend · −2 binary descend
B29: INDEX + MATCH (horizontal equivalent — still asked in banks)
B30: INDEX( return_row , MATCH( lookup_value , lookup_row , 0 ) )
B31: Two-way: INDEX( matrix , MATCH(row_key, row_headers, 0) , MATCH(col_key, col_headers, 0) )
B33: SIDE-BY-SIDE COMPARISON (memorise the Default column)
B34: Capability | C34: HLOOKUP | D34: VLOOKUP | E34: XLOOKUP | F34: INDEX + MATCH
B35: Looks up on | C35: Top row (horizontal) | D35: Left column (vertical) | E35: Any row or column | F35: Any row or column
B36: Can return left / above? | C36: No — only rows below | D36: No — only cols to the right* | E36: Yes | F36: Yes
B37: Default match | C37: Approximate TRUE | D37: Approximate TRUE | E37: Exact 0 | F37: Exact if match_type = 0
B38: Not-found handling | C38: IFNA / IFERROR wrap | D38: IFNA / IFERROR wrap | E38: Built-in 4th argument | F38: IFNA wrap
B39: Search last match | C39: No native way | D39: No native way | E39: search_mode = −1 | F39: LOOKUP / XMATCH −1
B40: Wildcard | C40: Only with exact + * ? | D40: Only with exact + * ? | E40: match_mode = 2 | F40: MATCH wildcards
B41: Insert row/col safe? | C41: No (row_index breaks) | D41: No (col_index breaks) | E41: Yes if arrays are correct | F41: Yes if MATCH on headers
B42: Return many columns | C42: No (one row index) | D42: No (one col index) | E42: Yes — spill a block | F42: INDEX with array
B43: Approx needs sorted? | C43: Yes, first row ascending | D43: Yes, first col ascending | E43: Yes for ±1 match_mode | F43: Yes for match_type ±1
B44: Works in Excel 2016? | C44: Yes | D44: Yes | E44: No | F44: Yes
B45: Interview verdict | C45: Know it; rarely ship it | D45: Still everywhere in legacy | E45: Default choice in 365 | F45: Fallback + two-way gold
B47: * VLOOKUP can return left only if you rearrange the table or switch to INDEX/MATCH / XLOOKUP. Saying “VLOOKUP can look left if I copy the key column” is acceptable; saying it natively looks left is wrong.
B49: EIGHT SENTENCES INTERVIEWERS WANT TO HEAR
B50: 1 | C50: HLOOKUP searches the first row of table_array and returns a value from a row you specify by number — that number is brittle.
B51: 2 | C51: HLOOKUP and VLOOKUP default to approximate match; if you omit the last argument you can get a silent wrong answer.
B52: 3 | C52: Approximate match is correct for tax slabs, credit scores, and commission tiers, but the breakpoint row must be sorted ascending.
B53: 4 | C53: XLOOKUP separates the search array from the return array, so the return column can sit to the left of the key.
B54: 5 | C54: XLOOKUP’s 4th argument replaces IFERROR for missing keys and does not swallow real errors like #DIV/0! the way IFERROR does.
B55: 6 | C55: Two-way lookup = MATCH on the row headers plus MATCH on the column headers, then INDEX; or nested XLOOKUP.
...

Sheet Sheet1
A4: Helper | B4: Region
A5: 1 | B5: East
A6: 2 | B6: East
A7: 3 | B7: East
A8: 4 | B8: East
A9: 5 | B9: West
A10: 6 | B10: West
A11: 7 | B11: West
A12: 8 | B12: West
A13: 9 | B13: North
A14: 10 | B14: North
A15: 11 | B15: North
A16: 12 | B16: North
... A20: 16 | B20: South

Sheet Sheet2
A1: 10000
A3: Helper | B3: Sales
A4: 1 | B4: =RANDBETWEEN(10,10000) -> 8636
A5: 2 | B5: =RANDBETWEEN(10,10000) -> 9099
A6: 3 | B6: =RANDBETWEEN(10,10000) -> 7323
A7: 4 | B7: =RANDBETWEEN(10,10000) -> 2725
A8: 5 | B8: =RANDBETWEEN(10,10000) -> 6441
A9: 6 | B9: =RANDBETWEEN(10,10000) -> 4486
A10: 7 | B10: =RANDBETWEEN(10,10000) -> 6614
A11: 8 | B11: =RANDBETWEEN(10,10000) -> 488
A12: 9 | B12: =RANDBETWEEN(10,10000) -> 7405
A13: 10 | B13: =RANDBETWEEN(10,10000) -> 904
A14: 11 | B14: =RANDBETWEEN(10,10000) -> 8495
A15: 12 | B15: =RANDBETWEEN(10,10000) -> 9773
... A19: 16 | B19: =RANDBETWEEN(10,10000) -> 5184

Sheet Sheet3
A3: Helper | B3: Region | C3: Sales
A4: 1 | B4: =Sheet1!B5 -> East | C4: =Sheet2!B4 -> 8636
A5: 2 | B5: =Sheet1!B6 -> East | C5: =Sheet2!B5 -> 9099
A6: 3 | B6: =Sheet1!B7 -> East | C6: =Sheet2!B6 -> 7323
A7: 4 | B7: =Sheet1!B8 -> East | C7: =Sheet2!B7 -> 2725
A8: 5 | B8: =Sheet1!B9 -> West | C8: =Sheet2!B8 -> 6441
A9: 6 | B9: =Sheet1!B10 -> West | C9: =Sheet2!B9 -> 4486
A10: 7 | B10: =Sheet1!B11 -> West | C10: =Sheet2!B10 -> 6614 | E10: Helper | F10: Region | G10: Sales
A11: 8 | B11: =Sheet1!B12 -> West | C11: =Sheet2!B11 -> 488 | E11: 1 | F11: =VLOOKUP(E11,Sheet1!A4:B20,2,FALSE) -> East | G11: =VLOOKUP(E11,Sheet2!A3:B19,2,FALSE) -> 8636
A12: 9 | B12: =Sheet1!B13 -> North | C12: =Sheet2!B12 -> 7405 | E12: 2 | F12: =VLOOKUP(E12,Sheet1!A5:B21,2,FALSE) -> East | G12: =VLOOKUP(E12,Sheet2!A4:B20,2,FALSE) -> 9099
A13: 10 | B13: =Sheet1!B14 -> North | C13: =Sheet2!B13 -> 904 | E13: 3 | F13: =VLOOKUP(E13,Sheet1!A6:B22,2,FALSE) -> East | G13: =VLOOKUP(E13,Sheet2!A5:B21,2,FALSE) -> 7323
A14: 11 | B14: =Sheet1!B15 -> North | C14: =Sheet2!B14 -> 8495 | E14: 4 | F14: =VLOOKUP(E14,Sheet1!A7:B23,2,FALSE) -> East | G14: =VLOOKUP(E14,Sheet2!A6:B22,2,FALSE) -> 2725
A15: 12 | B15: =Sheet1!B16 -> North | C15: =Sheet2!B15 -> 9773 | E15: 5 | F15: =VLOOKUP(E15,Sheet1!A8:B24,2,FALSE) -> West | G15: =VLOOKUP(E15,Sheet2!A7:B23,2,FALSE) -> 6441
A16: 13 | B16: =Sheet1!B17 -> South | C16: =Sheet2!B16 -> 702 | E16: 6 | F16: =VLOOKUP(E16,Sheet1!A9:B25,2,FALSE) -> West | G16: =VLOOKUP(E16,Sheet2!A8:B24,2,FALSE) -> 4486
A17: 14 | B17: =Sheet1!B18 -> South | C17: =Sheet2!B17 -> 8752 | E17: 7 | F17: =VLOOKUP(E17,Sheet1!A10:B26,2,FALSE) -> West | G17: =VLOOKUP(E17,Sheet2!A9:B25,2,FALSE) -> 6614
A18: 15 | B18: =Sheet1!B19 -> South | C18: =Sheet2!B18 -> 1533 | E18: 8 | F18: =VLOOKUP(E18,Sheet1!A11:B27,2,FALSE) -> West | G18: =VLOOKUP(E18,Sheet2!A10:B26,2,FALSE) -> 488
A19: 16 | B19: =Sheet1!B20 -> South | C19: =Sheet2!B19 -> 5184 | E19: 9 | F19: =VLOOKUP(E19,Sheet1!A12:B28,2,FALSE) -> North | G19: =VLOOKUP(E19,Sheet2!A11:B27,2,FALSE) -> 7405
E20: 10 | F20: =VLOOKUP(E20,Sheet1!A13:B29,2,FALSE) -> North | G20: =VLOOKUP(E20,Sheet2!A12:B28,2,FALSE) -> 904
E21: 11 | F21: =VLOOKUP(E21,Sheet1!A14:B30,2,FALSE) -> North | G21: =VLOOKUP(E21,Sheet2!A13:B29,2,FALSE) -> 8495
E22: 12 | F22: =VLOOKUP(E22,Sheet1!A15:B31,2,FALSE) -> North | G22: =VLOOKUP(E22,Sheet2!A14:B30,2,FALSE) -> 9773
E23: 13 | F23: =VLOOKUP(E23,Sheet1!A16:B32,2,FALSE) -> South | G23: =VLOOKUP(E23,Sheet2!A15:B31,2,FALSE) -> 702
E24: 14 | F24: =VLOOKUP(E24,Sheet1!A17:B33,2,FALSE) -> South | G24: =VLOOKUP(E24,Sheet2!A16:B32,2,FALSE) -> 8752
E25: 15 | F25: =VLOOKUP(E25,Sheet1!A18:B34,2,FALSE) -> South | G25: =VLOOKUP(E25,Sheet2!A17:B33,2,FALSE) -> 1533
E26: 16 | F26: =VLOOKUP(E26,Sheet1!A19:B35,2,FALSE) -> South | G26: =VLOOKUP(E26,Sheet2!A18:B34,2,FALSE) -> 5184

Sheet 02-HLOOKUP-Basics
B1: HLOOKUP BASICS · Apex Retail monthly trading matrix (₹ lakh)
B2: Source table is horizontal: months run across the top row — this is the only shape HLOOKUP is designed for.
B4: SOURCE · FY2026 MONTHLY KPI PACK (green = lookup table) | K4: ROW INDEX MAP (for table $B$5:$H$12)
B5: KPI \ Month | C5: Jan | D5: Feb | E5: Mar | F5: Apr | G5: May | H5: Jun | K5: row_index | L5: Sheet row | M5: KPI
B6: Revenue | C6: 42.5 | D6: 38 | E6: 51.2 | F6: 47.8 | G6: 55 | H6: 61.4 | K6: 1 | L6: 5 | M6: Month headers (rarely returned)
B7: COGS | C7: 25.5 | D7: 22.4 | E7: 29.7 | F7: 27.9 | G7: 31.4 | H7: 35 | K7: 2 | L7: 6 | M7: Revenue
B8: Gross Profit | C8: =C6-C7 -> 17 | D8: =D6-D7 -> 15.6 | E8: =E6-E7 -> 21.5 | F8: =F6-F7 -> 19.9 | G8: =G6-G7 -> 23.6 | H8: =H6-H7 -> 26.4 | K8: 3 | L8: 7 | M8: COGS
B9: Units ('000) | C9: 18.2 | D9: 16 | E9: 21.5 | F9: 19.8 | G9: 23 | H9: 25.6 | K9: 4 | L9: 8 | M9: Gross Profit
B10: ASP (₹) | C10: =IF(C9=0,0,C6*100/C9) -> 233.51648 | D10: =IF(D9=0,0,D6*100/D9) -> 237.5 | E10: =IF(E9=0,0,E6*100/E9) -> 238.13953 | F10: =IF(F9=0,0,F6*100/F9) -> 241.41414 | G10: =IF(G9=0,0,G6*100/G9) -> 239.13043 | H10: =IF(H9=0,0,H6*100/H9) -> 239.84375 | K10: 5 | L10: 9 | M10: Units ('000)
B11: Target Rev | C11: 40 | D11: 40 | E11: 48 | F11: 48 | G11: 52 | H11: 58 | K11: 6 | L11: 10 | M11: ASP (₹)
B12: Discount % | C12: 0.08 | D12: 0.1 | E12: 0.07 | F12: 0.09 | G12: 0.06 | H12: 0.05 | K12: 7 | L12: 11 | M12: Target Rev
B13: HLOOKUP row_index → | K13: 8 | L13: 12 | M13: Discount %
K14: Interview point: if someone inserts a row between COGS and GP, every hardcoded row_index below that insertion silently shifts. That is why MATCH exists.
B16: EXAMPLE 1 · EXACT MATCH range_lookup = FALSE
B17: Task: return May Revenue. Lookup month in the first row, return row_index 2 (Revenue).
B18: Month (input) | C18: Jan
B19: Row index (input) | C19: 2
B20: Result (₹ lakh) | C20: =HLOOKUP(C18,$C$5:$H$12,C19,FALSE()) -> 42.5
B22: Why $C$5 not $B$5? Because the first row of table_array must contain the lookup values (months). Including the KPI labels in column B would make HLOOKUP search "KPI \ Month", "Revenue", … and never find "May".
B24: EXAMPLE 2 · WHAT EXACT MATCH DOES WITH A MISSING KEY
B25: Month (input) | C25: Jul
B26: Raw HLOOKUP | C26: =HLOOKUP(C25,$C$5:$H$12,2,FALSE()) -> #N/A
B27: Wrapped IFNA | C27: =IF(ISNA(HLOOKUP(C25,$C$5:$H$12,2,FALSE())),"No month in pack",HLOOKUP(C25,$C$5:$H$12,2,FALSE())) -> No month in pack
B28: '=IFNA( HLOOKUP(C25,$C$5:$H$12,2,FALSE) , "No month in pack" )
B29: Prefer IFNA over IFERROR. IFERROR also hides #REF!, #DIV/0!, #VALUE! — which means a broken row_index looks like “not found”. Interviewers notice.
B31: EXAMPLE 3 · APPROXIMATE MATCH range_lookup = TRUE (sorted breakpoints)
B32: Use case: convert a score into a grade. Breakpoints sit on the first row and MUST be sorted ascending. HLOOKUP walks the first row until the next breakpoint would exceed the score, then steps back.
B33: Min score → | C33: 0 | D33: 40 | E33: 50 | F33: 60 | G33: 75 | H33: 90
B34: Grade | C34: F | D34: D | E34: C | F34: B | G34: A | H34: A+
B35: Meaning | C35: Fail | D35: Pass | E35: Average | F35: Good | G35: Excellent | H35: Outstanding
B37: Score (input) | C37: 76
B38: Grade | C38: =HLOOKUP(C37,$C$33:$H$35,2,TRUE()) -> A
B39: Meaning | C39: =HLOOKUP(C37,$C$33:$H$35,3,TRUE()) -> Excellent
B40: '=HLOOKUP( C37 , $C$33:$H$35 , 2 , TRUE )
B41: Walkthrough for 76: first row is 0 · 40 · 50 · 60 · 75 · 90. 76 ≥ 75 and 76 < 90, so HLOOKUP locks onto the 75 column and returns row 2 of that column = A.
B43: TRAP · APPROXIMATE MATCH ON UNSORTED DATA RETURNS GARBAGE, NOT AN ERROR
B44: Unsorted breakpoints below. Same score 76. Compare the two results. This is the question that separates people who memorised syntax from people who have been burned.
B45: Min score → | C45: 0 | D45: 90 | E45: 50 | F45: 75 | G45: 40 | H45: 60
B46: Grade | C46: F | D46: A+ | E46: C | F46: A | G46: D | H46: B
B48: Score | C48: =C37 -> 76
...

Sheet 03-HLOOKUP-Advanced
B1: HLOOKUP ADVANCED · MATCH · TWO-WAY · SLABS · INTERVIEW PATTERNS
B2: If you only remember one pattern from this sheet: HLOOKUP + MATCH(kpi, kpi_column, 0) so row_index is never hardcoded.
B4: SOURCE A · SKU PRICE CARD BY QUARTER (₹ / unit) | K4: SOURCE B · UNITS BY REGION × MONTH
B5: SKU \ Quarter | C5: Q1 | D5: Q2 | E5: Q3 | F5: Q4 | K5: Region | L5: Jan | M5: Feb | N5: Mar | O5: Apr
B6: SKU-1040 Cotton Tee | C6: 399 | D6: 379 | E6: 349 | F6: 399 | K6: North | L6: 420 | M6: 390 | N6: 510 | O6: 470
B7: SKU-1042 Denim Jacket | C7: 2499 | D7: 2299 | E7: 2199 | F7: 2599 | K7: West | L7: 380 | M7: 360 | N7: 440 | O7: 455
B8: SKU-1055 Runner Shoe | C8: 3199 | D8: 3199 | E8: 2899 | F8: 3499 | K8: South | L8: 510 | M8: 495 | N8: 560 | O8: 530
B9: SKU-1071 Canvas Tote | C9: 799 | D9: 749 | E9: 699 | F9: 849 | K9: East | L9: 240 | M9: 220 | N9: 265 | O9: 250
B10: SKU-1088 Wool Scarf | C10: 1299 | D10: 999 | E10: 899 | F10: 1499 | K10: Export | L10: 180 | M10: 175 | N10: 210 | O10: 198
B12: SOURCE C · QUARTERLY COMMISSION SLAB (sorted breakpoints)
B13: Sales ≥ ₹ lakh | C13: 0 | D13: 20 | E13: 35 | F13: 50 | G13: 75 | H13: 100
B14: Commission % | C14: 0.02 | D14: 0.03 | E14: 0.04 | F14: 0.055 | G14: 0.07 | H14: 0.09
B15: Payout month | C15: Apr | D15: Apr | E15: Jul | F15: Jul | G15: Oct | H15: Jan
B17: PATTERN 1 · DYNAMIC ROW INDEX WITH MATCH
B18: Do not type 4. Look up the KPI name in column B and feed MATCH’s result into HLOOKUP’s row_index. MATCH is 1-based relative to the range you give it.
B19: Month | C19: Apr
B20: KPI name | C20: Gross Profit
B21: MATCH row_index | C21: =MATCH(C20,'02-HLOOKUP-Basics'!$B$5:$B$12,0) -> 4
B22: HLOOKUP result | C22: =HLOOKUP(C19,'02-HLOOKUP-Basics'!$C$5:$H$12,C21,FALSE()) -> 19.9
B23: =HLOOKUP(C19,'02-HLOOKUP-Basics'!B5:H12,4,FALSE) -> 19.9
B24: Cross-sheet reference is intentional — interviewers love “the matrix is on another tab”. Green font is not applied here because we keep one font system; just notice the sheet name in the formula.
B26: PATTERN 2 · TWO-WAY LOOKUP (region × month) HLOOKUP + MATCH
B27: HLOOKUP finds the month column. MATCH finds which row the region sits on, relative to the table_array’s first row.
B28: Region | C28: South
B29: Month | C29: Mar
B30: MATCH row_index | C30: =MATCH(C28,$K$5:$K$10,0) -> 4
B31: Units | C31: =HLOOKUP(C29,$L$5:$O$10,C30,FALSE()) -> 560
B32: =HLOOKUP(C29,K5:O10,MATCH(C28,K5:K10,0),FALSE) -> 560
B33: table_array starts at L5 (first month), NOT K5. MATCH range starts at K5 so that row_index 1 = header, 2 = North, … 4 = South. Off-by-one here is the most common lab failure.
B34: INDEX/MATCH/MATCH | C34: =INDEX($L$6:$O$10,MATCH(C28,$K$6:$K$10,0),MATCH(C29,$L$5:$O$5,0)) -> 560
B35: '=INDEX( matrix , MATCH(region, region_list, 0) , MATCH(month, month_list, 0) ) ← prefer this in interviews if XLOOKUP is not allowed
B37: PATTERN 3 · SLAB LOOKUP + PAYOUT CALCULATION
B38: Rep sales ₹ lakh | C38: 58
B39: Commission % | C39: =HLOOKUP(C38,$C$13:$H$15,2,TRUE()) -> 0.055
B40: Payout month | C40: =HLOOKUP(C38,$C$13:$H$15,3,TRUE()) -> Jul
B41: Commission ₹ lakh | C41: =C38*C39 -> 3.19
B42: '=HLOOKUP( sales , $C$13:$H$15 , 2 , TRUE ) 58 sits in the ≥50 and <75 bucket → 5.5%
B44: PATTERN 4 · NESTED HLOOKUP (price card → then apply a quarter-specific discount)
B45: Inner HLOOKUP gets list price. Outer logic applies Q3 extra markdown of 8% if quarter = Q3, else 0. Interviewers nest to see if you keep ranges absolute.
B46: SKU full label | C46: SKU-1042 Denim Jacket
...

Sheet 04_XLOOKUP_Basics
B1: XLOOKUP BASICS · EXACT · NOT-FOUND · HORIZONTAL · WILDCARD
B2: Requires Excel 365 / 2021. Default match is EXACT. You no longer pass a row index — you pass the return row/column itself.
B4: SOURCE · EMPLOYEE ROSTER (vertical keys — XLOOKUP native shape) | K4: SOURCE · DEPT TARGETS BY MONTH (₹ lakh)
B5: Emp ID | C5: Name | D5: Dept | E5: Band | F5: Location | G5: Manager ID | H5: CTC ₹ L | K5: Dept | L5: Jan | M5: Feb | N5: Mar | O5: Apr
B6: E-1001 | C6: Ananya Rao | D6: Finance | E6: L5 | F6: Mumbai | G6: E-1200 | H6: 18.5 | K6: Finance | L6: 4 | M6: 4 | N6: 4.5 | O6: 4.5
B7: E-1002 | C7: Vikram Shah | D7: Ops | E7: L4 | F7: Pune | G7: E-1201 | H7: 12 | K7: Ops | L7: 12 | M7: 11.5 | N7: 13 | O7: 12.5
B8: E-1003 | C8: Meera Iyer | D8: Finance | E8: L4 | F8: Bengaluru | G8: E-1200 | H8: 11.2 | K8: Merch | L8: 18 | M8: 17 | N8: 20 | O8: 19
B9: E-1004 | C9: Rohit Nair | D9: Merch | E9: L3 | F9: Mumbai | G9: E-1202 | H9: 8.4 | K9: Tech | L9: 6 | M9: 6 | N9: 6.5 | O9: 6.5
B10: E-1005 | C10: Sara Khan | D10: Ops | E10: L5 | F10: Delhi | G10: E-1201 | H10: 16.8
B11: E-1006 | C11: Arjun Patel | D11: Merch | E11: L4 | F11: Ahmedabad | G11: E-1202 | H11: 10.5
B12: E-1007 | C12: Neha Gupta | D12: Tech | E12: L6 | F12: Bengaluru | G12: E-1203 | H12: 28
B13: E-1008 | C13: Farhan Ali | D13: Tech | E13: L5 | F13: Hyderabad | G13: E-1203 | H13: 19.4
B14: E-1009 | C14: Priya Das | D14: Finance | E14: L3 | F14: Kolkata | G14: E-1200 | H14: 7.8
B15: E-1010 | C15: Karan Mehta | D15: Ops | E15: L3 | F15: Pune | G15: E-1201 | H15: 7.2
B16: E-1200 | C16: Leela Menon | D16: Finance | E16: L7 | F16: Mumbai | G16: E-1300 | H16: 42
B17: E-1201 | C17: Dev Kapoor | D17: Ops | E17: L7 | F17: Delhi | G17: E-1300 | H17: 38.5
B18: E-1202 | C18: Ishita Bose | D18: Merch | E18: L6 | F18: Mumbai | G18: E-1300 | H18: 31
B19: E-1203 | C19: Nikhil Rao | D19: Tech | E19: L7 | F19: Bengaluru | G19: E-1300 | H19: 46
B21: EXAMPLE 1 · VERTICAL EXACT (replace VLOOKUP) | K21: EXAMPLE 4 · HORIZONTAL XLOOKUP (HLOOKUP replacement)
B22: Emp ID | C22: E-1005 | K22: Dept | L22: Merch
B23: Name | C23: =_xlfn.XLOOKUP(C22,$B$6:$B$19,$C$6:$C$19) -> Sara Khan | K23: Month | L23: Mar
B24: Dept | C24: =_xlfn.XLOOKUP(C22,$B$6:$B$19,$D$6:$D$19) -> Ops | K24: Target ₹ L | L24: =_xludf.xlookup(L23,$L$5:$O$5,_xludf.xlookup(L22,$K$6:$K$9,$L$6:$O$9),"No combo") -> #NAME?
B25: CTC ₹ L | C25: =_xlfn.XLOOKUP(C22,$B$6:$B$19,$H$6:$H$19) -> 16.8 | K25: '=XLOOKUP( month , month_headers , XLOOKUP(dept, dept_list, matrix) )
B26: =XLOOKUP( C22 , $B$6:$B$19 , $C$6:$C$19 ) | K26: Inner XLOOKUP returns the whole row $L$6:$O$9 filtered to Merch. Outer XLOOKUP then treats that row as return_array and the month headers as lookup_array. This is the modern two-way lookup.
B27: Contrast with VLOOKUP: =VLOOKUP(C22,$B$6:$H$19,2,FALSE). XLOOKUP does not care that Name is column 2. If someone inserts a column between ID and Name, XLOOKUP still works; VLOOKUP breaks.
K28: REWRITE THE HLOOKUP FROM SHEET 02
B29: EXAMPLE 2 · if_not_found (4th argument) | K29: Old: =HLOOKUP(month, $C$5:$H$12, 2, FALSE) for Revenue. New: point lookup_array at the month headers and return_array at the Revenue row.
B30: Emp ID | C30: E-1999 | K30: Month | L30: May
B31: Name raw | C31: =_xludf.xlookup(C30,$B$6:$B$19,$C$6:$C$19) -> #NAME? | K31: Revenue XLOOKUP | L31: =_xludf.xlookup(L30,'02-HLOOKUP-Basics'!$C$5:$H$5,'02-HLOOKUP-Basics'!$C$6:$H$6,"No month") -> #NAME?
B32: Name guarded | C32: =_xludf.xlookup(C30,$B$6:$B$19,$C$6:$C$19,"ID not on roster") -> #NAME? | K32: '=XLOOKUP( month , header_row , revenue_row , "No month" )
B33: '=XLOOKUP( C30 , $B$6:$B$19 , $C$6:$C$19 , "ID not on roster" )
B34: 4th argument fires only on no-match. A broken range still surfaces #REF!. That is the point versus IFERROR(XLOOKUP(...),"missing").
B36: EXAMPLE 3 · LOOKUP TO THE LEFT (VLOOKUP cannot do this natively)
B37: We have Manager ID on each row. Resolve it to Manager Name by looking up that ID in the same roster — return array is to the RIGHT of the key here, but the pattern also works if Name sat to the left of ID.
B38: Emp ID | C38: E-1007
B39: Manager ID | C39: =_xludf.xlookup(C38,$B$6:$B$19,$G$6:$G$19,"—") -> #NAME?
B40: Manager name | C40: =_xludf.xlookup(C39,$B$6:$B$19,$C$6:$C$19,"CEO / not listed") -> #NAME?
B41: Nested: =XLOOKUP( XLOOKUP(id, IDs, ManagerIDs) , IDs , Names , "CEO / not listed" )
B43: EXAMPLE 5 · WILDCARD match_mode = 2
B44: match_mode 2 turns * and ? on. * = any run of characters, ? = one character, ~ escapes a literal * or ?.
...

Sheet 05_XLOOKUP_Advanced
B1: XLOOKUP ADVANCED · SEARCH MODES · APPROX · MULTI-CRITERIA · LOGS
B2: This is the sheet that wins interviews. Last-to-first + two-way + a clean not-found message is the expected senior-analyst answer.
B4: SOURCE · STOCK MOVEMENT LOG (duplicate SKUs — order is chronological) | K4: SOURCE · FY26 INCOME TAX SLAB (new regime, illus.)
B5: Line | C5: Date | D5: SKU | E5: Event | F5: Qty | G5: Warehouse | H5: Unit Cost | K5: Income ≥ | L5: Rate | M5: Cess on tax
B6: 1 | C6: 2026-01-06 | D6: SKU-1042 | E6: IN | F6: 40 | G6: BHI | H6: 1480 | K6: 0 | L6: 0 | M6: 0.04
B7: 2 | C7: 2026-01-09 | D7: SKU-1040 | E7: IN | F7: 200 | G7: BHI | H7: 210 | K7: 300000 | L7: 0.05 | M7: 0.04
B8: 3 | C8: 2026-01-12 | D8: SKU-1042 | E8: OUT | F8: 12 | G8: BHI | H8: 1480 | K8: 700000 | L8: 0.1 | M8: 0.04
B9: 4 | C9: 2026-01-18 | D9: SKU-1055 | E9: IN | F9: 60 | G9: PNQ | H9: 1980 | K9: 1000000 | L9: 0.15 | M9: 0.04
B10: 5 | C10: 2026-01-22 | D10: SKU-1042 | E10: OUT | F10: 8 | G10: BHI | H10: 1480 | K10: 1200000 | L10: 0.2 | M10: 0.04
B11: 6 | C11: 2026-02-02 | D11: SKU-1040 | E11: OUT | F11: 40 | G11: BHI | H11: 210 | K11: 1500000 | L11: 0.3 | M11: 0.04
B12: 7 | C12: 2026-02-11 | D12: SKU-1042 | E12: IN | F12: 25 | G12: PNQ | H12: 1510 | K12: Sorted ascending. XLOOKUP match_mode −1 = exact or next smaller — same idea as HLOOKUP TRUE, but the lookup array is a column.
B13: 8 | C13: 2026-02-14 | D13: SKU-1071 | E13: IN | F13: 80 | G13: BHI | H13: 390
B14: 9 | C14: 2026-02-20 | D14: SKU-1042 | E14: OUT | F14: 15 | G14: PNQ | H14: 1510 | K14: SOURCE · COURIER SLAB (next larger weight)
B15: 10 | C15: 2026-03-03 | D15: SKU-1055 | E15: OUT | F15: 20 | G15: PNQ | H15: 1980 | K15: Max kg | L15: Charge ₹
B16: 11 | C16: 2026-03-15 | D16: SKU-1042 | E16: OUT | F16: 10 | G16: PNQ | H16: 1510 | K16: 0.5 | L16: 49
B17: 12 | C17: 2026-03-28 | D17: SKU-1040 | E17: IN | F17: 150 | G17: PNQ | H17: 205 | K17: 1 | L17: 69
K18: 2 | L18: 99
B19: PATTERN 1 · LAST MATCH search_mode = −1 | K19: 5 | L19: 149
B20: SKU-1042 appears on lines 1,3,5,7,9,11. First-to-last returns the January receipt. Last-to-first returns the 15-Mar outbound — “current state” from a log. | K20: 10 | L20: 219
B21: SKU | C21: SKU-1042 | K21: 20 | L21: 349
B22: First event date | C22: =_xludf.xlookup(C21,$D$6:$D$17,$C$6:$C$17,"none",0,1) -> #NAME?
B23: Last event date | C23: =_xludf.xlookup(C21,$D$6:$D$17,$C$6:$C$17,"none",0,-1) -> #NAME?
B24: Last event type | C24: =_xludf.xlookup(C21,$D$6:$D$17,$E$6:$E$17,"none",0,-1) -> #NAME?
B25: Last warehouse | C25: =_xludf.xlookup(C21,$D$6:$D$17,$G$6:$G$17,"none",0,-1) -> #NAME?
B26: Last unit cost | C26: =_xludf.xlookup(C21,$D$6:$D$17,$H$6:$H$17,"none",0,-1) -> #NAME?
B27: '=XLOOKUP( sku , SKU_col , Date_col , "none" , 0 , -1 )
B28: Argument order you must not swap: match_mode is 5th, search_mode is 6th. Passing −1 in the 5th slot means “next smaller”, not “search backwards”.
B30: PATTERN 2 · NEXT SMALLER match_mode = −1 (tax slab)
B31: Taxable income ₹ | C31: 950000
B32: Marginal rate | C32: =_xludf.xlookup(C31,$K$6:$K$11,$L$6:$L$11,"check slab",-1) -> #NAME?
B33: Cess rate | C33: =_xludf.xlookup(C31,$K$6:$K$11,$M$6:$M$11,"check slab",-1) -> #NAME?
B34: '=XLOOKUP( income , breakpoints , rates , "check slab" , -1 )
B35: 950,000 is not in the list. Next smaller breakpoint is 700,000 → 10%. This is the XLOOKUP equivalent of VLOOKUP/HLOOKUP TRUE.
B37: PATTERN 3 · NEXT LARGER match_mode = 1 (courier billable weight)
B38: A 1.2 kg parcel is not 1 kg and not 2 kg. Billing rule: charge the next band up. match_mode 1 = exact or next larger.
B39: Actual kg | C39: 1.2
B40: Billable band kg | C40: =_xludf.xlookup(C39,$K$16:$K$21,$K$16:$K$21,"Over 20kg desk",1) -> #NAME?
B41: Charge ₹ | C41: =_xludf.xlookup(C39,$K$16:$K$21,$L$16:$L$21,"Over 20kg desk",1) -> #NAME?
B42: '=XLOOKUP( kg , max_kg , charge , "Over 20kg desk" , 1 )
B43: If actual kg exceeds the last breakpoint, XLOOKUP with match_mode 1 returns if_not_found. That is the correct behaviour — do not let it silently pick 20 kg.
...

Sheet 06_Practice_Lab
B1: PRACTICE LAB · 15 PROBLEMS · ATTEMPT BEFORE YOU OPEN 07_Solutions
B2: Yellow = your formula. Grey = locked prompt. Data lives on this sheet so you are not hunting tabs under time pressure.
B4: LAB DATA · do not edit · ranges are named in the prompts
B5: Metric | C5: Jan | D5: Feb | E5: Mar | F5: Apr | G5: May | H5: Jun
B6: Sales | C6: 120 | D6: 132 | E6: 128 | F6: 141 | G6: 155 | H6: 160
B7: Returns | C7: 8 | D7: 11 | E7: 9 | F7: 10 | G7: 12 | H7: 9
B8: NPS | C8: 42 | D8: 44 | E8: 39 | F8: 47 | G8: 51 | H8: 53
B10: Code | C10: Rep | D10: Region | E10: Q1 sales | F10: Q2 sales | G10: Status
B11: R01 | C11: A. Rao | D11: West | E11: 42 | F11: 48 | G11: Active
B12: R02 | C12: V. Shah | D12: North | E12: 35 | F12: 31 | G12: Active
B13: R03 | C13: M. Iyer | D13: South | E13: 51 | F13: 57 | G13: Active
B14: R04 | C14: R. Nair | D14: West | E14: 22 | F14: 19 | G14: Exited
B15: R05 | C15: S. Khan | D15: North | E15: 47 | F15: 55 | G15: Active
B16: R06 | C16: P. Das | D16: East | E16: 18 | F16: 24 | G16: Active
B17: R07 | C17: K. Mehta | D17: South | E17: 29 | F17: 33 | G17: Active
B18: R08 | C18: F. Ali | D18: West | E18: 40 | F18: 40 | G18: Active
B20: Q2 sales ≥ | C20: 0 | D20: 20 | E20: 30 | F20: 40 | G20: 50 | H20: 60
B21: Bonus % | C21: 0 | D21: 0.02 | E21: 0.04 | F21: 0.06 | G21: 0.09 | H21: 0.12
B22: Badge | C22: — | D22: Bronze | E22: Silver | F22: Gold | G22: Platinum | H22: Diamond
B24: Tkt | C24: Rep | D24: Opened | E24: Issue | F24: State
B25: T-01 | C25: R01 | D25: 2026-04-02 | E25: Late delivery | F25: Closed
B26: T-02 | C26: R03 | D26: 2026-04-03 | E26: Size swap | F26: Closed
B27: T-03 | C27: R01 | D27: 2026-04-10 | E27: Refund | F27: Open
B28: T-04 | C28: R05 | D28: 2026-04-12 | E28: Late delivery | F28: Closed
B29: T-05 | C29: R03 | D29: 2026-04-18 | E29: Refund | F29: Open
B30: T-06 | C30: R01 | D30: 2026-04-21 | E30: Missing item | F30: Open
B31: T-07 | C31: R08 | D31: 2026-04-22 | E31: Size swap | F31: Closed
B32: T-08 | C32: R05 | D32: 2026-04-28 | E32: Refund | F32: Open
B34: PROBLEMS · type formulas in column F · inputs in column E are already filled — change them to test
B35: # | C35: Level | D35: Prompt | E35: Input | F35: YOUR FORMULA → | G35: Hint (not the answer)
B36: 01 | C36: ★ H | D36: Exact HLOOKUP: Sales for month in E36. Table B5:H8. | E36: May | F36: =HLOOKUP(E36,B5:H8,2,FALSE) -> 155 | G36: Month headers must be the first row of table_array.
B37: 02 | C37: ★ H | D37: Exact HLOOKUP: NPS for month in E37. | E37: Feb | F37: =HLOOKUP(E37,B5:H8,4,FALSE) -> 44 | G37: Count rows from the first row of the range you pass.
B38: 03 | C38: ★★ H | D38: HLOOKUP+MATCH: return the metric named in E38 for month in E39. | E38: Returns | F38: =HLOOKUP(E39,B5:H8,MATCH(E38,B5:B8,0),FALSE) -> 9 | G38: MATCH metric against B5:B8. Month sits in E39.
D39: ↑ month input for Q03 is E39 | E39: Mar | G39: Do not put the Q03 formula here. E39 is an input only.
B40: 04 | C40: ★★ H | D40: Approx HLOOKUP: Bonus % for Q2 sales figure in E40. Slab rows 20-22. | E40: 48 | F40: =HLOOKUP(E40,B20:H22,2,TRUE) -> 0.06 | G40: TRUE / sorted breakpoints C20:H20. row_index of Bonus %.
B41: 05 | C41: ★★ H | D41: Approx HLOOKUP: Badge for Q2 sales in E41. | E41: 55 | F41: =HLOOKUP(E41,B20:H22,3,TRUE) -> Platinum | G41: Same slab, different row_index.
B42: 06 | C42: ★★ H | D42: IFNA + exact HLOOKUP: Sales for month in E42. Fake months → Missing month | E42: Nov | F42: =IFERROR(HLOOKUP(E42,B5:H8,2,FALSE),"Missing month") -> Missing month | G42: IFNA wraps HLOOKUP, not IFERROR.
B43: 07 | C43: ★ X | D43: XLOOKUP: Rep name for code in E43. Staff B11:C18. | E43: R05 | F43: =_xlfn.XLOOKUP(E43,B11:B18,C11:C18,"Not Found",0,1) -> S. Khan | G43: lookup B11:B18, return C11:C18.
B44: 08 | C44: ★ X | D44: XLOOKUP + if_not_found: name for code in E44. | E44: R99 | F44: =_xlfn.XLOOKUP(E44,B11:B18,C11:C18,"No such rep",0) -> No such rep | G44: 4th argument "No such rep".
B45: 09 | C45: ★★ X | D45: Horizontal XLOOKUP: Sales for month in E45. | E45: Apr | F45: =_xlfn.XLOOKUP(E45,C5:H5,C6:H6,"No Data",0) -> 141 | G45: lookup C5:H5, return C6:H6.
...

Sheet 07_Solutions
B1: SOLUTIONS · COMPARE AFTER YOU ATTEMPT · LIVE FORMULAS POINT AT 06_Practice_Lab
B2: Each solution uses the lab sheet inputs, so if you change a yellow input on the lab, the solution result here updates.
B4: ANSWER KEY
B5: # | C5: Type | D5: Formula (study this) | E5: Live result | F5: Why this shape
B6: 01 | C6: HLOOKUP | D6: '=HLOOKUP('06_Practice_Lab'!E36,'06_Practice_Lab'!$C$5:$H$8,2,FALSE) | E6: =HLOOKUP('06_Practice_Lab'!E36,'06_Practice_Lab'!$C$5:$H$8,2,FALSE()) -> 155 | F6: Row 2 of C5:H8 is Sales. FALSE because month names are not a sorted numeric slab.
B7: 02 | C7: HLOOKUP | D7: '=HLOOKUP('06_Practice_Lab'!E37,'06_Practice_Lab'!$C$5:$H$8,4,FALSE) | E7: =HLOOKUP('06_Practice_Lab'!E37,'06_Practice_Lab'!$C$5:$H$8,4,FALSE()) -> 44 | F7: Header=1, Sales=2, Returns=3, NPS=4. Off-by-one is the usual miss.
B8: 03 | C8: HLOOKUP+MATCH | D8: '=HLOOKUP('06_Practice_Lab'!E39,'06_Practice_Lab'!$C$5:$H$8,MATCH('06_Practice_Lab'!E38,'06_Practice_Lab'!$B$5:$B$8,0),FALSE) | E8: =HLOOKUP('06_Practice_Lab'!E39,'06_Practice_Lab'!$C$5:$H$8,MATCH('06_Practice_Lab'!E38,'06_Practice_Lab'!$B$5:$B$8,0),FALSE()) -> 9 | F8: MATCH and HLOOKUP ranges share the same top row (row 5). That keeps row_index aligned.
B9: 04 | C9: HLOOKUP TRUE | D9: '=HLOOKUP('06_Practice_Lab'!E40,'06_Practice_Lab'!$C$20:$H$21,2,TRUE) | E9: =HLOOKUP('06_Practice_Lab'!E40,'06_Practice_Lab'!$C$20:$H$21,2,TRUE()) -> 0.06 | F9: Slab first row is breakpoints, second is bonus %. 48 sits in ≥40 and <50 → 6%.
B10: 05 | C10: HLOOKUP TRUE | D10: '=HLOOKUP('06_Practice_Lab'!E41,'06_Practice_Lab'!$C$20:$H$22,3,TRUE) | E10: =HLOOKUP('06_Practice_Lab'!E41,'06_Practice_Lab'!$C$20:$H$22,3,TRUE()) -> Platinum | F10: Badge is the third row of the slab block C20:H22. 55 → Platinum.
B11: 06 | C11: IFNA+HLOOKUP | D11: '=IF(ISNA(HLOOKUP('06_Practice_Lab'!E42,'06_Practice_Lab'!$C$5:$H$8,2,FALSE)),"Missing month",HLOOKUP('06_Practice_Lab'!E42,'06_Practice_Lab'!$C$5:$H$8,2,FALSE)) | E11: =IF(ISNA(HLOOKUP('06_Practice_Lab'!E42,'06_Practice_Lab'!$C$5:$H$8,2,FALSE())),"Missing month",HLOOKUP('06_Practice_Lab'!E42,'06_Practice_Lab'!$C$5:$H$8,2,FALSE())) -> Missing month | F11: Nov is absent. In Excel prefer IFNA(HLOOKUP(...),"Missing month"). IFERROR would also hide a bad row_index.
B12: 07 | C12: XLOOKUP | D12: '=XLOOKUP('06_Practice_Lab'!E43,'06_Practice_Lab'!$B$11:$B$18,'06_Practice_Lab'!$C$11:$C$18) | E12: =_xludf.xlookup('06_Practice_Lab'!E43,'06_Practice_Lab'!$B$11:$B$18,'06_Practice_Lab'!$C$11:$C$18) -> #NAME? | F12: Classic VLOOKUP replacement. Return array is independent of column position.
B13: 08 | C13: XLOOKUP 4th | D13: '=XLOOKUP('06_Practice_Lab'!E44,'06_Practice_Lab'!$B$11:$B$18,'06_Practice_Lab'!$C$11:$C$18,"No such rep") | E13: =_xludf.xlookup('06_Practice_Lab'!E44,'06_Practice_Lab'!$B$11:$B$18,'06_Practice_Lab'!$C$11:$C$18,"No such rep") -> #NAME? | F13: R99 is not in the list. 4th argument fires. No IFERROR needed.
B14: 09 | C14: XLOOKUP horiz | D14: '=XLOOKUP('06_Practice_Lab'!E45,'06_Practice_Lab'!$C$5:$H$5,'06_Practice_Lab'!$C$6:$H$6) | E14: =_xludf.xlookup('06_Practice_Lab'!E45,'06_Practice_Lab'!$C$5:$H$5,'06_Practice_Lab'!$C$6:$H$6) -> #NAME? | F14: This is the one-line HLOOKUP replacement. No row_index.
B15: 10 | C15: XLOOKUP −1 | D15: '=XLOOKUP('06_Practice_Lab'!E46,'06_Practice_Lab'!$C$25:$C$32,'06_Practice_Lab'!$F$25:$F$32,"none",0,-1) | E15: =_xludf.xlookup('06_Practice_Lab'!E46,'06_Practice_Lab'!$C$25:$C$32,'06_Practice_Lab'!$F$25:$F$32,"none",0,-1) -> #NAME? | F15: R01 tickets: T-01 Closed, T-03 Open, T-06 Open. Last match = Open.
B16: 11 | C16: XLOOKUP 2-crit | D16: '=XLOOKUP(1,('06_Practice_Lab'!$C$25:$C$32='06_Practice_Lab'!E47)*('06_Practice_Lab'!$F$25:$F$32="Open"),'06_Practice_Lab'!$E$25:$E$32,"none",0,-1) | E16: =_xludf.xlookup(1,('06_Practice_Lab'!$C$25:$C$32='06_Practice_Lab'!E47)*('06_Practice_Lab'!$F$25:$F$32="Open"),'06_Practice_Lab'!$E$25:$E$32,"none",0,-1) -> #NAME? | F16: Boolean AND produces 1/0. Search for 1 from the bottom. R01 last open issue = Missing item.
B17: 12 | C17: Nested XLOOKUP | D17: '=XLOOKUP(XLOOKUP('06_Practice_Lab'!E48,'06_Practice_Lab'!$B$11:$B$18,'06_Practice_Lab'!$F$11:$F$18),'06_Practice_Lab'!$C$20:$H$20,'06_Practice_Lab'!$C$21:$H$21,"—",-1) | E17: =_xludf.xlookup(_xludf.xlookup('06_Practice_Lab'!E48,'06_Practice_Lab'!$B$11:$B$18,'06_Practice_Lab'!$F$11:$F$18),'06_Practice_Lab'!$C$20:$H$20,'06_Practice_Lab'!$C$21:$H$21,"—",-1) -> #NAME? | F17: R03 Q2 = 57 → next-smaller breakpoint 50 → 9%. Inner lookup must be Q2 column F, not Q1.
B18: 13 | C18: Double XLOOKUP | D18: '=XLOOKUP(XLOOKUP('06_Practice_Lab'!E49,'06_Practice_Lab'!$E$25:$E$32,'06_Practice_Lab'!$C$25:$C$32,"none",0,-1),'06_Practice_Lab'!$B$11:$B$18,'06_Practice_Lab'!$D$11:$D$18,"none") | E18: =_xludf.xlookup(_xludf.xlookup('06_Practice_Lab'!E49,'06_Practice_Lab'!$E$25:$E$32,'06_Practice_Lab'!$C$25:$C$32,"none",0,-1),'06_Practice_Lab'!$B$11:$B$18,'06_Practice_Lab'!$D$11:$D$18,"none") -> #NAME? | F18: Last Refund ticket is T-08 (R05). R05 region = North.
B19: 14 | C19: XLOOKUP rewrite | D19: '=XLOOKUP('06_Practice_Lab'!E50,'06_Practice_Lab'!$C$5:$H$5,'06_Practice_Lab'!$C$6:$H$6,"Missing month") | E19: =_xludf.xlookup('06_Practice_Lab'!E50,'06_Practice_Lab'!$C$5:$H$5,'06_Practice_Lab'!$C$6:$H$6,"Missing month") -> #NAME? | F19: Same question as 01. If your Q01 and Q14 results differ for the same month, one of them is wrong.
B20: 15 | C20: Two-way XLOOKUP | D20: '=XLOOKUP('06_Practice_Lab'!E52,'06_Practice_Lab'!$C$5:$H$5,XLOOKUP('06_Practice_Lab'!E51,'06_Practice_Lab'!$B$6:$B$8,'06_Practice_Lab'!$C$6:$H$8)) | E20: =_xludf.xlookup('06_Practice_Lab'!E52,'06_Practice_Lab'!$C$5:$H$5,_xludf.xlookup('06_Practice_Lab'!E51,'06_Practice_Lab'!$B$6:$B$8,'06_Practice_Lab'!$C$6:$H$8)) -> #NAME? | F20: Inner returns the whole metric row (3 months? 6 months). Outer picks the month. INDEX/MATCH/MATCH is equally valid.
B22: ALTERNATE ANSWER FOR Q15 (INDEX / MATCH / MATCH) — equally interview-valid
B23: '=INDEX('06_Practice_Lab'!$C$6:$H$8, MATCH(E51,'06_Practice_Lab'!$B$6:$B$8,0), MATCH(E52,'06_Practice_Lab'!$C$5:$H$5,0))
B24: =INDEX('06_Practice_Lab'!$C$6:$H$8,MATCH('06_Practice_Lab'!E51,'06_Practice_Lab'!$B$6:$B$8,0),MATCH('06_Practice_Lab'!E52,'06_Practice_Lab'!$C$5:$H$5,0)) -> 39 | C24: Live INDEX/MATCH/MATCH result →
B25: If XLOOKUP is disabled by IT policy or the file must open in Excel 2016, this is the answer you write on the whiteboard.
B27: EXPECTED LIVE RESULTS WITH THE DEFAULT INPUTS
B28: 01 May Sales | C28: 155 | E28: 09 Apr Sales | F28: 141
B29: 02 Feb NPS | C29: 44 | E29: 10 R01 last state | F29: Open
B30: 03 Returns / Mar | C30: 9 | E30: 11 R01 last open issue | F30: Missing item
B31: 04 Bonus on 48 | C31: 6% | E31: 12 R03 bonus % | F31: 9%
B32: 05 Badge on 55 | C32: Platinum | E32: 13 Last Refund region | F32: North
B33: 06 Nov Sales | C33: Missing month | E33: 14 Jun Sales | F33: 160
B34: 07 R05 name | C34: S. Khan | E34: 15 NPS / Mar | F34: 39
B35: 08 R99 name | C35: No such rep
B37: If a live result shows #NAME?, you are not in Excel 365/2021. Use the HLOOKUP / INDEX answers only and read the XLOOKUP formulas as syntax study.

Sheet 08_Interview_QA
B1: INTERVIEW Q&A · 20 QUESTIONS · MODEL ANSWERS YOU CAN SAY OUT LOUD
B2: Cover this sheet and try to answer in one or two sentences. Then reveal. The sentences match the eight talking points on the cheatsheet.
B4: BANK OF QUESTIONS
B5: # | C5: Theme | D5: Question + model answer
B6: Q01 | C6: Basics | D6: What does HLOOKUP actually search?
D7: The first row of table_array only. row_index_num then counts down from that first row, starting at 1. It cannot search a middle row and it cannot return a row above the first row.
B8: Q02 | C8: Basics | D8: Why is HLOOKUP’s last argument a trap?
D9: It defaults to TRUE (approximate). If you omit it, Excel will not error — it will return a nearby value from a range it treats as sorted. Always pass FALSE unless you have sorted numeric breakpoints.
B10: Q03 | C10: Basics | D10: When is approximate match the correct tool?
D11: Slabs: tax bands, exam grades, commission tiers, shipping weight bands. The breakpoint row/column must be sorted ascending. Say “sorted algorithm, not nearest neighbour”.
B12: Q04 | C12: Basics | D12: HLOOKUP vs VLOOKUP in one line.
D13: HLOOKUP looks across the top and returns from a row below. VLOOKUP looks down the left and returns from a column to the right. Same four arguments, same default-TRUE trap.
B14: Q05 | C14: Design | D14: Why do seniors tell you not to ship HLOOKUP?
D15: row_index_num is a magic number. Insert a row inside the table and every formula below the insertion is silently wrong. MATCH or XLOOKUP removes that class of bug.
B16: Q06 | C16: Design | D16: How do you make HLOOKUP insertion-safe?
D17: Replace the hardcoded row_index with MATCH(kpi_name, kpi_labels, 0), and make sure MATCH’s range and HLOOKUP’s table_array start on the same row so the index stays aligned.
B18: Q07 | C18: Design | D18: Write a two-way lookup three ways.
D19: 1) INDEX(matrix, MATCH(row_key, row_heads,0), MATCH(col_key, col_heads,0)). 2) HLOOKUP(col_key, values, MATCH(row_key, row_heads,0), FALSE). 3) XLOOKUP(col_key, col_heads, XLOOKUP(row_key, row_heads, matrix)).
B20: Q08 | C20: XLOOKUP | D20: Name all six XLOOKUP arguments in order.
D21: lookup_value, lookup_array, return_array, if_not_found, match_mode, search_mode. Mixing up 5 and 6 is the most common XLOOKUP bug — −1 in slot 5 means next-smaller, not last-to-first.
B22: Q09 | C22: XLOOKUP | D22: Default match_mode and search_mode?
D23: 0 (exact) and 1 (first-to-last). That is the opposite default to VLOOKUP/HLOOKUP, and it is why XLOOKUP is safer in messy data.
B24: Q10 | C24: XLOOKUP | D24: How do you return the most recent transaction for an ID?
D25: Keep the log in chronological order and use search_mode −1. Do not sort the sheet descending just to make a first-match work — that breaks everyone else.
B26: Q11 | C26: XLOOKUP | D26: Exact or next smaller vs next larger — when each?
D27: −1 next smaller: income tax, grades, “sales ≥ breakpoint”. 1 next larger: courier bands billed to the next weight up, “capacity must be at least X”.
B28: Q12 | C28: XLOOKUP | D28: Why is if_not_found better than IFERROR?
D29: if_not_found runs only when the key is missing. IFERROR also hides #REF!, #DIV/0!, #VALUE!, so a broken range looks like a missing employee. I use IFNA if I must wrap an older function.
B30: Q13 | C30: XLOOKUP | D30: Can XLOOKUP look left?
D31: Yes. lookup_array and return_array are independent. The return column can sit anywhere. That is the headline advantage over VLOOKUP.
B32: Q14 | C32: XLOOKUP | D32: How do you do two criteria with no helper column?
D33: '=XLOOKUP(1, (A:A=id)*(B:B=status), C:C, "none", 0, -1). The boolean product is the lookup_array. Mention that Excel 365 handles the array natively; 2016 needs a helper column.
B34: Q15 | C34: Compare | D34: XLOOKUP vs INDEX/MATCH — when do you still use INDEX/MATCH?
D35: When the workbook must open in Excel 2016/2019, when a shared Sheets user is in the loop and you want the older common subset, or when you already have MATCH results reused across several INDEX calls (one MATCH, many INDEX).
B36: Q16 | C36: Compare | D36: Does XLOOKUP make INDEX/MATCH obsolete for two-way work?
D37: No. INDEX/MATCH/MATCH is still the most portable two-way pattern and many banking model standards still require it. Nested XLOOKUP is cleaner in 365 and I use it when the file standard allows.
B38: Q17 | C38: Traps | D38: A candidate writes HLOOKUP(A1, C5:H12, 2) and gets a plausible but wrong number. Diagnose.
D39: Fourth argument omitted → approximate match. Month text is not sorted the way the algorithm expects, so Excel returned an adjacent month’s revenue. Fix: add FALSE, or switch to XLOOKUP.
B40: Q18 | C40: Traps | D40: Approximate HLOOKUP on unsorted breakpoints. What happens?
D41: No error. Wrong grade / wrong tax / wrong commission. I treat unsorted + TRUE as a production incident, not a style issue.
...
