Workbook
Name Sales_Region: Data_Sales!$C$5:$C$154
Name Sales_Revenue: Data_Sales!$L$5:$L$154

Sheet 00_Instructions
A1: EXCEL HANDS-ON ASSESSMENT • 40 QUESTIONS
A2: Board pack · Slice the book · Join HR and product files · Build scoreboards · Read the charts · Recommend a plan
A4: Purpose
A5: This workbook is a practical Excel test written the way work arrives on an analyst’s desk: a business question, a messy-enough file, and a number or recommendation due by end of day. The questions do not name the function. You decide whether the job needs a total, a filter, a lookup, a pivot, or a written read of a chart. Do not overwrite source data on the Data_* sheets. Type every answer into the yellow cells on 01_Questions. Use 02_Workspace for helper calculations and pivots.
A8: Test rules
A9: Suggested time | B9: 90–120 minutes
A10: Total questions | B10: 40
A11: Total marks | B11: 100
A12: Pass guideline | B12: 70 / 100 (trainers may set their own cut-off)
A13: Excel version | B13: Microsoft Excel 2021 / Microsoft 365 recommended (some directory lookups are easier on 365).
A14: Allowed aids | B14: This workbook only. No internet, no Copilot, no prior files.
A15: Rounding | B15: Currency to 2 decimals. Percentages to 1 decimal unless the question says otherwise. Correlation to 4 decimals.
A16: Lookups | B16: Match the exact product / person unless the ticket is a rate slab or band, where the next-lower threshold is the rule.
A18: Workbook map
A19: Sheet | B19: What it contains
A20: 00_Instructions | B20: You are here. Read fully before starting.
A21: 01_Questions | B21: All 40 questions. Yellow cells = your answers. Do not change question text.
A22: 02_Workspace | B22: Blank working area. Build helper columns, pivots and the pivot chart here.
A23: Data_Sales | B23: 150 sales orders (Jan–Jun 2025). Primary fact table. Table name: SalesData.
A24: Data_Products | B24: 14-item product catalogue. Table name: Products. Use for price / cost lookups.
A25: Data_Employees | B25: 14-row employee directory. Table name: Employees. Use for salary / manager lookups.
A26: Data_Targets | B26: Horizontal monthly targets (HLOOKUP / XLOOKUP). Commission slabs for approximate VLOOKUP.
A27: Data_Charts | B27: Pre-aggregated views plus four charts used in Q35–Q40. Do not delete the charts.
A28: 03_Answer_Key | B28: Instructor use. Hide or delete this sheet before issuing the test.
A30: Question mix and marks
A31: Questions | B31: Theme | C31: What you will actually do | D31: Marks
A32: Q1–Q12 | B32: Daily reporting | C32: Totals, averages, counts, one- and two-filter slices, rounding, a pass/fail flag, a date label, a slide title | D32: 24
A33: Q13–Q18 | B33: Shape of the numbers | C33: Typical vs average invoice, most common basket, spread, large-order cut-off, ranking, whether units and revenue actually move together | D33: 12
A34: Q19–Q28 | B34: Joining files | C34: Price from a product code, a junk code, a bonus slab, a target sitting across months, salary and manager from HR, a name that is not on payroll, cost from a product name | D34: 28
A35: Q29–Q34 | B35: Scoreboards | C35: Refreshable region, category×channel and rep views, a monthly grouping, a mix-of-total view, a meeting chart tied to the scoreboard | D35: 18
A36: Q35–Q40 | B36: What the charts are saying | C36: Read the four charts and write a recommendation a sales lead could act on | D36: 18
A37: Total | D37: 100
A40: How to answer
A41: 1. Read the ticket and the Dataset hint. Source tables start at row 1 with headers. Nothing in the question will name SUMIF, VLOOKUP, XLOOKUP, and so on — that is the point.
A42: 2. For number tickets, put a live formula in the yellow cell. A typed-in number that happens to be right scores half marks, because the file will be refreshed next month.
A43: 3. For the scoreboard tickets (Q29–Q34), build the views on 02_Workspace at the labelled anchors, then type the resulting name or number into the yellow cell on 01_Questions.
A44: 4. For the chart tickets (Q35–Q40), write 2–4 sentences. Marks are for a specific observation + a number from this file + what a manager should do with it.
A45: 5. Lookups should survive a missing code or a missing employee without spilling #N/A onto a slide. Recover with a clean message when the ticket asks for one.
A46: 6. Tables you may point at: SalesData, Products, Employees, Targets, Commission. Structured references or ordinary ranges are both fine.
A47: 7. When you finish, every yellow cell on 01_Questions should be filled. Leave 03_Answer_Key alone if that sheet is in your file.
...

Sheet 01_Questions
A1: QUESTION PAPER • TYPE EVERY ANSWER IN COLUMN F (YELLOW)
A2: 40 live analyst tickets · 100 marks · Questions describe the business need, not the function. Choose the Excel approach yourself. Data sits on the Data_* sheets. Build pivots on 02_Workspace.
A3: Candidate name | B3: Badal Pradip Lad | D3: ID | F3: Assessor total | G3: =SUM(G8:G47) -> 0
A7: Q# | B7: Theme | C7: Marks | D7: Question | E7: YOUR ANSWER | F7: Workings (optional) | G7: Marks given
A8: 1 | B8: Reporting | C8: 2 | D8: Finance is closing H1. They need the company’s total billed revenue from every order on the sales file — one number they can drop into the board pack. | E8: =SUM(Sales_Revenue) -> 131833.75 | F8: sum
A9: 2 | B9: Reporting | C9: 2 | D9: Ops wants a sense of typical basket size. What is the average number of units on an order across the whole book? | E9: =AVERAGE(Data_Sales!I5:I154) -> 9.9 | F9: avg
A10: 3 | B10: Reporting | C10: 2 | D10: The CRM team thinks some orders never landed in Excel. How many distinct orders are actually on the sales file? | E10: =COUNTA(Data_Sales!A5:A154) -> 150 | F10: counta
A11: 4 | B11: Reporting | C11: 2 | D11: A key-account manager asked whether any single invoice is large enough to need extra credit approval. What is the highest revenue on one order? Note the Order ID in workings. | E11: =MAX(Sales_Revenue) -> 8091 | F11: max
A12: 5 | B12: Reporting | C12: 2 | D12: The West regional head has been told her book is carrying the company. Pull West’s total revenue so she can take it into her weekly stand-up. | E12: =SUMIF(Sales_Region,"West",Sales_Revenue) -> 46874.85 | F12: sumif
A13: 6 | B13: Reporting | C13: 2 | D13: Category management is reviewing assortment. How many orders included an Electronics item? | E13: =COUNTIF(Data_Sales!H4:H154,"Electronics") -> 79 | F13: countif
A14: 7 | B14: Reporting | C14: 2 | D14: The e-commerce lead suspects Online baskets are bulkier than store baskets. What is the average units per Online order? | E14: =AVERAGEIF(Data_Sales!M5:M154,"Online",Sales_Revenue) -> 857.93986 | F14: AVERAGEIF()
A15: 8 | B15: Reporting | C15: 2 | D15: Marketing ran a North + Online campaign in Q1. How much revenue came from that exact slice (North region and Online channel together)? | E15: =SUMIFS(Data_Sales!L4:L154,Data_Sales!C4:C154,"North",Data_Sales!M4:M154,"Online") -> 12141.22 | F15: SUMIFS()
A16: 9 | B16: Reporting | C16: 2 | D16: The CFO does not want paise in the headline KPI. Take the average revenue per order and report it as a whole-rupee figure. | E16: =AVERAGE(Sales_Revenue) -> 878.89167 | F16: AVERAGE()
A17: 10 | B17: Reporting | C17: 2 | D17: Leadership set a West H1 floor of ₹40,000. Flag the region as Hit if West revenue clears that floor, otherwise Miss. Put only Hit or Miss in the answer cell. | E17: =IF(SUMIF(Sales_Region,"West",Sales_Revenue)>=40000,"HIT","MISS") -> HIT | F17: if + sumif
A18: 11 | B18: Reporting | C18: 2 | D18: Audit asked which calendar month the sales file starts in. From the first order date on Data_Sales, return the full month name (for example January). | E18: =MONTH(MIN(Data_Sales!B5:B154)) -> 1 | I18: East | J18: West | K18: North | L18: South
A19: 12 | B19: Reporting | C19: 2 | D19: Comms needs a one-cell slide title: the leading region’s name followed by the words " leads revenue". Build that label in the answer cell. | E19: West | I19: =SUMIF(Sales_Region,"East",Sales_Revenue) -> 27747.09 | J19: =SUMIF(Sales_Region,"West",Sales_Revenue) -> 46874.85 | K19: =SUMIF(Sales_Region,"North",Sales_Revenue) -> 28196.26 | L19: =SUMIF(Sales_Region,"South",Sales_Revenue) -> 29015.55
A20: 13 | B20: Distribution | C20: 2 | D20: Average invoice is being skewed by a few large deals. What revenue sits in the middle of the order book if you line every order up from smallest to largest? | E20: =MEDIAN(Sales_Revenue) -> 483.52 | F20: Median | I20: East | J20: West | K20: North | L20: South
A21: 14 | B21: Distribution | C21: 2 | D21: Warehouse pick-faces are planned around the most common order quantity. Which units value appears most often on the sales file? | E21: =_xlfn.MODE.SNGL(Data_Sales!I125:I154) -> 4 | F21: Mode
A22: 15 | B22: Distribution | C22: 2 | D22: Risk wants to know how widely invoice values swing around the average — the sample spread of revenue across these 150 orders, not the whole-population version. | E22: =_xlfn.STDEV.S(Sales_Revenue) -> 1044.0575 | F22: STDEV.S()
A23: 16 | B23: Distribution | C23: 2 | D23: Credit wants a ‘large order’ cut-off: the revenue level that 75% of orders fall at or below. | E23: =_xlfn.PERCENTILE.INC(Sales_Revenue,0.75) -> 1338.2225 | F23: PERCENTILE.INC()
A24: 17 | B24: Distribution | C24: 2 | D24: For the exception report, rank every order by revenue with the biggest invoice as rank 1. What rank does that biggest invoice receive? | E24: =_xlfn.XLOOKUP(1,Data_Sales!P5:P154,Sales_Revenue) -> 8091 | F24: rank -> helper column
A25: 18 | B25: Distribution | C25: 2 | D25: A junior analyst claimed ‘more units always means more revenue’. Measure how tightly units and revenue move together. Report the relationship to 4 decimal places. | E25: =CORREL(Data_Sales!I5:I154,Sales_Revenue) -> -0.056784786 | F25: CORREL()
A26: 19 | B26: Join files | C26: 3 | D26: A warehouse scan came back as product code EL-1001 with no price attached. Pull the catalogue list price from the product file so billing can raise the invoice. | E26: {=_xlfn.XLOOKUP("EL-1001",Products[[#All],[ProductCode]],Products[[#All],[ListPrice]])} -> 899 | F26: XLOOKUP()
A27: 20 | B27: Join files | C27: 3 | D27: The same scan sometimes sends junk codes. Look up ZZ-9999 on the product file. If it is not a real product, the cell should read Not listed rather than an error. | E27: {=IFERROR(_xlfn.XLOOKUP("ZZ-9999",Products[[#All],[ProductCode]],Products[[#All],[ProductName]]),"Not Listed")} -> Not Listed | F27: XLOOKUP()
A28: 21 | B28: Join files | C28: 3 | D28: HR runs a simple slab bonus: find West’s total H1 revenue, then read the matching commission rate from the slab table on Data_Targets. Return the rate as a percentage. | E28: {=_xlfn.XLOOKUP(SUMIF(Sales_Region,"West",Sales_Revenue),Commission[[#All],[MinSales]],Commission[[#All],[CommissionRate]],"Not Found",-1)} -> 0.03 | F28: XLOOKUP() + sumif()
A29: 22 | B29: Join files | C29: 2 | D29: FP&A laid monthly revenue targets out across the top of a grid (Jan in one column, Feb in the next, and so on). What revenue target was set for March? | E29: =HLOOKUP("Mar",Data_Targets!A4:G5,2,FALSE) -> 52000 | F29: HLOOKUP()
A30: 23 | B30: Join files | C30: 2 | D30: CX reviews NPS against a monthly target on that same horizontal grid. What NPS target was set for April? | E30: =HLOOKUP("Apr",Targets[#All],5,FALSE) -> 65 | F30: HLOOKUP()
A31: 24 | B31: Join files | C31: 3 | D31: Payroll is checking a query from Priya Sharma. From the employee directory, what is her base salary? | E31: =VLOOKUP("Priya Sharma",Employees[[#All],[FullName]:[BaseSalary]],5,FALSE) -> 58000 | F31: VLOOKUP()
A32: 25 | B32: Join files | C32: 3 | D32: Ananya Roy appears on the sales file but HR is not sure she is on payroll. Look her up in the employee directory. If she is missing, return Contract associate so Finance can process her as a vendor. | E32: =IFERROR(VLOOKUP("Ananya Roy",Employees[[#All],[FullName]],1,FALSE)," Contract associate") -> Contract associate | F32: IFERROR(VLOOKUP())
A33: 26 | B33: Join files | C33: 3 | D33: Karan Singh raised a grievance that has to go to his line manager. From the directory, return his manager’s employee ID. Resolve the manager’s name in workings if you want. | E33: {=_xlfn.XLOOKUP("Karan Singh",Employees[[#All],[FullName]],Employees[[#All],[EmpID]],"Not Found")} -> E108 | F33: xlookup()
A34: 27 | B34: Join files | C34: 3 | D34: Costing has a product name, not a code: Standing Desk. The cost column does not sit next to the name. Still return the unit cost from the catalogue. | E34: {=_xlfn.XLOOKUP("Standing Desk",Products[[#All],[ProductName]],Products[[#All],[UnitCost]],"No Data Found",2)} -> 275
A35: 28 | B35: Join files | C35: 3 | D35: A pricing sheet is being rebuilt so anyone can type a product name and a field name. Using 27-inch Monitor as the product and UnitCost as the field, return that cost. In workings, also note gross margin (list price minus cost, over list price). | E35: =(J35-I35)/J35 -> 0.40860215 | H35: 27-inch Monitor | I35: =INDEX(Products[[#All],[UnitCost]],MATCH('01_Questions'!H35,Products[[#All],[ProductName]],0)) -> 165 | J35: =VLOOKUP(H35,Products[[#All],[ProductName]:[ListPrice]],3,FALSE) -> 279
A36: 29 | B36: Scoreboard | C36: 3 | D36: Commercial wants a live region scoreboard they can refresh next month. On 02_Workspace (start near A5) build a PivotTable of revenue by region. Which region is ahead? Type the name. | E36: West
A37: 30 | B37: Scoreboard | C37: 3 | D37: Category and channel owners keep arguing about who owns Furniture in Wholesale. On 02_Workspace (near A19) build a PivotTable with category down the side and channel across the top, revenue in the middle. What revenue sits at Furniture × Wholesale? | E37: 9978.4
A38: 31 | B38: Scoreboard | C38: 3 | D38: The sales director wants a rep ladder: who sold the most, and how many orders they wrote. Build that PivotTable on 02_Workspace (near A35), biggest revenue at the top. Type the leading rep’s name; put their revenue in workings. | E38: Sofia Dsouza
A39: 32 | B39: Scoreboard | C39: 3 | D39: Seasonality keeps surprising inventory. On 02_Workspace (near A53) put dates into a PivotTable and group them into months. Which month in H1 2025 did the most revenue? Type the month name. | E39: March
A40: 33 | B40: Scoreboard | C40: 3 | D40: The CEO thinks in shares, not rupees. On 02_Workspace (near A69) build a region PivotTable that shows each region’s revenue as a percentage of the company total. What share does West hold? One decimal place. | E40: 0.356
A41: 34 | B41: Scoreboard | C41: 3 | D41: The Monday sales meeting is on a screen, not a grid. Turn one of your PivotTables into a PivotChart and place it on 02_Workspace near A83. In the answer cell, name the chart shape you chose and why it fits the comparison you are showing. | E41: Column Chart — it clearly compares revenue across categories/regions, making the highest value easy to spot.
A42: 35 | B42: Insight | C42: 3 | D42: Look at Chart A on Data_Charts (revenue by region). Which region is ahead, and is that lead coming from more invoices, fatter invoices, or both? Cite at least one number from the table beside the chart. | E42: West
A43: 36 | B43: Insight | C43: 3 | D43: Charts B and B2 show the half-year by month and by channel. Which month peaked and which month was quietest? In the peak month, which channel actually did the heavy lifting? | E43: March peaked, January was quietest, and Retail did the heavy lifting in March.
...

Sheet Data_Sales
A1: SALES TRANSACTIONS • JANUARY–JUNE 2025
A2: 150 orders · Table name: SalesData · Revenue column is a formula (Units × UnitPrice × (1 − DiscountPct)). Do not sort this sheet in a way that breaks your answer formulas; copy to 02_Workspace if you need a custom sort.
A4: OrderID | B4: Date | C4: Region | D4: City | E4: SalesRep | F4: ProductCode | G4: Product | H4: Category | I4: Units | J4: UnitPrice | K4: DiscountPct | L4: Revenue | M4: Channel | N4: CustomerType | O4: Segment | P4: Helper
A5: ORD-5001 | B5: 45659 | C5: North | D5: Delhi | E5: Priya Sharma | F5: FN-2002 | G5: Standing Desk | H5: Furniture | I5: 1 | J5: 499 | K5: 0.12 | L5: =ROUND(I5*J5*(1-K5),2) -> 439.12 | M5: Online | N5: Returning | O5: Enterprise | P5: =RANK(L5,Sales_Revenue,0) -> 83
A6: ORD-5002 | B6: 45660 | C6: West | D6: Pune | E6: Sofia Dsouza | F6: OS-3001 | G6: A4 Paper Ream | H6: Office Supplies | I6: 26 | J6: 6.5 | K6: 0 | L6: =ROUND(I6*J6*(1-K6),2) -> 169 | M6: Online | N6: Returning | O6: Consumer | P6: =RANK(L6,Sales_Revenue,0) -> 122
A7: ORD-5003 | B7: 45664 | C7: East | D7: Lucknow | E7: Mohit Gupta | F7: FN-2002 | G7: Standing Desk | H7: Furniture | I7: 5 | J7: 499 | K7: 0.05 | L7: =ROUND(I7*J7*(1-K7),2) -> 2370.25 | M7: Retail | N7: Returning | O7: Enterprise | P7: =RANK(L7,Sales_Revenue,0) -> 10
A8: ORD-5004 | B8: 45672 | C8: West | D8: Mumbai | E8: Rahul Mehta | F8: EL-1003 | G8: USB-C Hub | H8: Electronics | I8: 6 | J8: 49 | K8: 0 | L8: =ROUND(I8*J8*(1-K8),2) -> 294 | M8: Online | N8: New | O8: Enterprise | P8: =RANK(L8,Sales_Revenue,0) -> 102
A9: ORD-5005 | B9: 45673 | C9: North | D9: Delhi | E9: Priya Sharma | F9: EL-1002 | G9: Wireless Mouse | H9: Electronics | I9: 1 | J9: 29 | K9: 0.1 | L9: =ROUND(I9*J9*(1-K9),2) -> 26.1 | M9: Wholesale | N9: Returning | O9: SMB | P9: =RANK(L9,Sales_Revenue,0) -> 150
A10: ORD-5006 | B10: 45679 | C10: South | D10: Hyderabad | E10: Neha Reddy | F10: FN-2001 | G10: Executive Chair | H10: Furniture | I10: 4 | J10: 349 | K10: 0.03 | L10: =ROUND(I10*J10*(1-K10),2) -> 1354.12 | M10: Online | N10: Returning | O10: SMB | P10: =RANK(L10,Sales_Revenue,0) -> 37
A11: ORD-5007 | B11: 45681 | C11: South | D11: Hyderabad | E11: Neha Reddy | F11: EL-1003 | G11: USB-C Hub | H11: Electronics | I11: 6 | J11: 49 | K11: 0.13 | L11: =ROUND(I11*J11*(1-K11),2) -> 255.78 | M11: Retail | N11: Returning | O11: SMB | P11: =RANK(L11,Sales_Revenue,0) -> 109
A12: ORD-5008 | B12: 45681 | C12: South | D12: Hyderabad | E12: Neha Reddy | F12: EL-1004 | G12: 27-inch Monitor | H12: Electronics | I12: 8 | J12: 279 | K12: 0.08 | L12: =ROUND(I12*J12*(1-K12),2) -> 2053.44 | M12: Online | N12: New | O12: Consumer | P12: =RANK(L12,Sales_Revenue,0) -> 15
A13: ORD-5009 | B13: 45681 | C13: East | D13: Kolkata | E13: Ananya Roy | F13: EL-1001 | G13: Laptop Pro 14 | H13: Electronics | I13: 3 | J13: 899 | K13: 0.08 | L13: =ROUND(I13*J13*(1-K13),2) -> 2481.24 | M13: Online | N13: New | O13: Enterprise | P13: =RANK(L13,Sales_Revenue,0) -> 6
A14: ORD-5010 | B14: 45681 | C14: West | D14: Mumbai | E14: Rahul Mehta | F14: FN-2002 | G14: Standing Desk | H14: Furniture | I14: 1 | J14: 499 | K14: 0.1 | L14: =ROUND(I14*J14*(1-K14),2) -> 449.1 | M14: Wholesale | N14: Returning | O14: SMB | P14: =RANK(L14,Sales_Revenue,0) -> 79
A15: ORD-5011 | B15: 45685 | C15: East | D15: Lucknow | E15: Mohit Gupta | F15: FN-2001 | G15: Executive Chair | H15: Furniture | I15: 2 | J15: 349 | K15: 0.1 | L15: =ROUND(I15*J15*(1-K15),2) -> 628.2 | M15: Wholesale | N15: Returning | O15: Enterprise | P15: =RANK(L15,Sales_Revenue,0) -> 68
A16: ORD-5012 | B16: 45687 | C16: East | D16: Kolkata | E16: Ananya Roy | F16: EL-1002 | G16: Wireless Mouse | H16: Electronics | I16: 7 | J16: 29 | K16: 0.12 | L16: =ROUND(I16*J16*(1-K16),2) -> 178.64 | M16: Online | N16: Returning | O16: SMB | P16: =RANK(L16,Sales_Revenue,0) -> 120
... A154: ORD-5150 | B154: 45838 | C154: West | D154: Pune | E154: Sofia Dsouza | F154: OS-3001 | G154: A4 Paper Ream | H154: Office Supplies | I154: 36 | J154: 6.5 | K154: 0.17 | L154: =ROUND(I154*J154*(1-K154),2) -> 194.22 | M154: Wholesale | N154: Key Account | O154: Enterprise | P154: =RANK(L154,Sales_Revenue,0) -> 118
H156: Check totals (formulas) | I156: =SUM(#REF!) -> #REF! | L156: =SUM(#REF!) -> #REF!

Sheet Data_Products
A1: PRODUCT CATALOGUE
A2: Lookup dimension · Table name: Products · Do not insert / delete rows inside the table during the test.
A4: ProductCode | B4: ProductName | C4: Category | D4: ListPrice | E4: UnitCost | F4: Supplier | G4: Warehouse
A5: EL-1001 | B5: Laptop Pro 14 | C5: Electronics | D5: 899 | E5: 620 | F5: NovaTech | G5: WH-A
A6: EL-1002 | B6: Wireless Mouse | C6: Electronics | D6: 29 | E6: 11 | F6: NovaTech | G6: WH-A
A7: EL-1003 | B7: USB-C Hub | C7: Electronics | D7: 49 | E7: 18 | F7: NovaTech | G7: WH-B
A8: EL-1004 | B8: 27-inch Monitor | C8: Electronics | D8: 279 | E8: 165 | F8: ViewMax | G8: WH-A
A9: EL-1005 | B9: Mechanical Keyboard | C9: Electronics | D9: 119 | E9: 54 | F9: ViewMax | G9: WH-B
A10: FN-2001 | B10: Executive Chair | C10: Furniture | D10: 349 | E10: 190 | F10: SitWell | G10: WH-C
A11: FN-2002 | B11: Standing Desk | C11: Furniture | D11: 499 | E11: 275 | F11: SitWell | G11: WH-C
A12: FN-2003 | B12: Bookshelf Oak | C12: Furniture | D12: 189 | E12: 95 | F12: Woodline | G12: WH-C
A13: OS-3001 | B13: A4 Paper Ream | C13: Office Supplies | D13: 6.5 | E13: 3.1 | F13: PaperCo | G13: WH-D
A14: OS-3002 | B14: Stapler Set | C14: Office Supplies | D14: 14 | E14: 5.5 | F14: PaperCo | G14: WH-D
A15: OS-3003 | B15: Ink Cartridge BK | C15: Office Supplies | D15: 32 | E15: 12 | F15: InkPro | G15: WH-D
A16: AP-4001 | B16: Polo Shirt | C16: Apparel | D16: 28 | E16: 11 | F16: ThreadCo | G16: WH-E
... A18: AP-4003 | B18: Cap Classic | C18: Apparel | D18: 16 | E18: 5.5 | F18: ThreadCo | G18: WH-E
A20: Notes for lookups
A21: ProductCode is unique. ProductName is also unique in this file. ListPrice is the catalogue price used on every sales order. UnitCost is used when costing asks for margin. Names and codes are both valid ways in; pick what the ticket gives you.

Sheet Data_Employees
A1: EMPLOYEE DIRECTORY
A2: Lookup dimension · Table name: Employees · ManagerID is blank for department heads.
A4: EmpID | B4: FullName | C4: Department | D4: JobTitle | E4: ManagerID | F4: BaseSalary | G4: Location | H4: PerformanceScore | I4: JoinDate
A5: E101 | B5: Aisha Khan | C5: Sales | D5: Regional Manager | F5: 92000 | G5: Mumbai | H5: 4.6 | I5: 43171
A6: E102 | B6: Rahul Mehta | C6: Sales | D6: Sales Executive | E6: E101 | F6: 54000 | G6: Mumbai | H6: 4.1 | I6: 44013
A7: E103 | B7: Priya Sharma | C7: Sales | D7: Sales Executive | E7: E101 | F7: 58000 | G7: Delhi | H7: 4.8 | I7: 43480
A8: E104 | B8: Vikram Patel | C8: Sales | D8: Sales Executive | E8: E101 | F8: 51000 | G8: Ahmedabad | H8: 3.7 | I8: 44503
A9: E105 | B9: Neha Reddy | C9: Sales | D9: Sales Executive | E9: E101 | F9: 56000 | G9: Hyderabad | H9: 4.4 | I9: 43881
A10: E106 | B10: Arjun Nair | C10: Sales | D10: Sales Executive | E10: E101 | F10: 53000 | G10: Bengaluru | H10: 3.9 | I10: 44690
A11: E107 | B11: Sofia Dsouza | C11: Sales | D11: Sales Executive | E11: E101 | F11: 55000 | G11: Pune | H11: 4.2 | I11: 43726
A12: E108 | B12: Karan Singh | C12: Sales | D12: Sales Executive | E12: E101 | F12: 50000 | G12: Jaipur | H12: 3.5 | I12: 45020
A13: E201 | B13: Meera Iyer | C13: Finance | D13: Finance Manager | F13: 98000 | G13: Mumbai | H13: 4.7 | I13: 42887
A14: E202 | B14: Dev Malhotra | C14: Finance | D14: Analyst | E14: E201 | F14: 62000 | G14: Mumbai | H14: 4 | I14: 44424
A15: E301 | B15: Anita Bose | C15: Operations | D15: Ops Manager | F15: 88000 | G15: Kolkata | H15: 4.3 | I15: 43395
A16: E302 | B16: Farhan Qureshi | C16: Operations | D16: Coordinator | E16: E301 | F16: 46000 | G16: Kolkata | H16: 3.8 | I16: 44571
A17: E401 | B17: Leena Joseph | C17: HR | D17: HR Manager | F17: 84000 | G17: Bengaluru | H17: 4.5 | I17: 42709
A18: E402 | B18: Rohit Das | C18: HR | D18: HR Executive | E18: E401 | F18: 42000 | G18: Bengaluru | H18: 3.6 | I18: 44971
A21: Helper: Manager name (optional — you may also look this up yourself) | D21: PerformanceScore is on a 1–5 scale. Ananya Roy and Mohit Gupta appear on the sales file but are contract / regional associates — they are intentionally absent from this directory.
A22: EmpID | B22: ManagerName
A23: E101 | B23: =IF(E5="","— Head of department",IFERROR(INDEX(Employees[FullName],MATCH(E5,Employees[EmpID],0)),"Not found")) -> — Head of department
A24: E102 | B24: =IF(E6="","— Head of department",IFERROR(INDEX(Employees[FullName],MATCH(E6,Employees[EmpID],0)),"Not found")) -> Aisha Khan
A25: E103 | B25: =IF(E7="","— Head of department",IFERROR(INDEX(Employees[FullName],MATCH(E7,Employees[EmpID],0)),"Not found")) -> Aisha Khan
A26: E104 | B26: =IF(E8="","— Head of department",IFERROR(INDEX(Employees[FullName],MATCH(E8,Employees[EmpID],0)),"Not found")) -> Aisha Khan
A27: E105 | B27: =IF(E9="","— Head of department",IFERROR(INDEX(Employees[FullName],MATCH(E9,Employees[EmpID],0)),"Not found")) -> Aisha Khan
A28: E106 | B28: =IF(E10="","— Head of department",IFERROR(INDEX(Employees[FullName],MATCH(E10,Employees[EmpID],0)),"Not found")) -> Aisha Khan
A29: E107 | B29: =IF(E11="","— Head of department",IFERROR(INDEX(Employees[FullName],MATCH(E11,Employees[EmpID],0)),"Not found")) -> Aisha Khan
A30: E108 | B30: =IF(E12="","— Head of department",IFERROR(INDEX(Employees[FullName],MATCH(E12,Employees[EmpID],0)),"Not found")) -> Aisha Khan
A31: E201 | B31: =IF(E13="","— Head of department",IFERROR(INDEX(Employees[FullName],MATCH(E13,Employees[EmpID],0)),"Not found")) -> — Head of department
A32: E202 | B32: =IF(E14="","— Head of department",IFERROR(INDEX(Employees[FullName],MATCH(E14,Employees[EmpID],0)),"Not found")) -> Meera Iyer
A33: E301 | B33: =IF(E15="","— Head of department",IFERROR(INDEX(Employees[FullName],MATCH(E15,Employees[EmpID],0)),"Not found")) -> — Head of department
A34: E302 | B34: =IF(E16="","— Head of department",IFERROR(INDEX(Employees[FullName],MATCH(E16,Employees[EmpID],0)),"Not found")) -> Anita Bose
... A36: E402 | B36: =IF(E18="","— Head of department",IFERROR(INDEX(Employees[FullName],MATCH(E18,Employees[EmpID],0)),"Not found")) -> Leena Joseph

Sheet Data_Targets
A1: MONTHLY TARGETS + COMMISSION SLABS
A2: Monthly targets sit across columns · Table name: Targets · Bonus slabs sit in Commission (sorted low → high)
A4: Metric | B4: Jan | C4: Feb | D4: Mar | E4: Apr | F4: May | G4: Jun
A5: Revenue Target | B5: 38000 | C5: 40000 | D5: 52000 | E5: 45000 | F5: 42000 | G5: 55000
A6: Units Target | B6: 280 | C6: 300 | D6: 380 | E6: 320 | F6: 300 | G6: 400
A7: Return Rate Cap | B7: 0.04 | C7: 0.04 | D7: 0.05 | E7: 0.04 | F7: 0.04 | G7: 0.05
A8: NPS Target | B8: 62 | C8: 64 | D8: 66 | E8: 65 | F8: 64 | G8: 68
A11: Commission slabs (find the highest threshold that the executive’s sales still clear, then take that rate)
A12: Find the largest threshold ≤ the sales executive’s year-to-June revenue, then return the rate.
A14: MinSales | B14: CommissionRate | D14: Example: revenue of ₹61,000 sits in the ₹50,000 slab and earns 4.5%. Keep the thresholds sorted ascending. The ticket is a banded rate, not an exact amount match.
A15: 0 | B15: 0.02
A16: 25000 | B16: 0.03
A17: 50000 | B17: 0.045
A18: 100000 | B18: 0.06
A19: 150000 | B19: 0.08
A22: Month number helper (optional)
A23: MonthNum | B23: Month
A24: 1 | B24: Jan
A25: 2 | B25: Feb
A26: 3 | B26: Mar
A27: 4 | B27: Apr
A28: 5 | B28: May
A29: 6 | B29: Jun

Sheet 02_Workspace
A1: CANDIDATE WORKSPACE • HELPERS, PIVOTS, PIVOT CHART
A2: Build every pivot and the pivot chart on this sheet. Suggested anchors are marked below. You may add helper columns anywhere to the right of column L.
A4: Q29 · Region scoreboard. Start a PivotTable at A5. Commercial want revenue by region, refreshable. | L4: Scratch / helper formulas
A6: Row Labels | B6: Sum of Revenue
A7: East | B7: 27747.09
A8: North | B8: 28196.26
A9: South | B9: 29015.55
A10: West | B10: 46874.85
A11: Grand Total | B11: 131833.75
A18: Q30 · Category × channel grid. Start a PivotTable at A19 so Furniture / Wholesale is a single readable cell.
A20: Sum of Revenue | B20: Column Labels
A21: Row Labels | B21: Online | C21: Retail | D21: Wholesale | E21: Grand Total
A22: Apparel | B22: 1006.2 | C22: 941.2 | D22: 764.06 | E22: 2711.46
A23: Electronics | B23: 35120.08 | C23: 24038.91 | D23: 15488.93 | E23: 74647.92
A24: Furniture | B24: 16090.4 | C24: 14028.14 | D24: 9978.4 | E24: 40096.94
A25: Office Supplies | B25: 7839.11 | C25: 2487.54 | D25: 4050.78 | E25: 14377.43
A26: Grand Total | B26: 60055.79 | C26: 41495.79 | D26: 30282.17 | E26: 131833.75
A34: Q31 · Rep ladder. Start a PivotTable at A35. Rank people by revenue; keep order count visible.
A36: Row Labels | B36: Sum of Revenue | C36: Count of OrderID
A37: Ananya Roy | B37: 13476.06 | C37: 15
A38: Arjun Nair | B38: 14910.01 | C38: 15
A39: Karan Singh | B39: 13666.14 | C39: 13
A40: Mohit Gupta | B40: 14271.03 | C40: 11
A41: Neha Reddy | B41: 14105.54 | C41: 17
A42: Priya Sharma | B42: 14530.12 | C42: 17
A43: Rahul Mehta | B43: 16002.91 | C43: 23
A44: Sofia Dsouza | B44: 22021.64 | C44: 24
A45: Vikram Patel | B45: 8850.3 | C45: 15
A46: Grand Total | B46: 131833.75 | C46: 150
A52: Q32 · Seasonality. Start a PivotTable at A53 and group the date field into months.
A54: Row Labels | B54: Sum of Revenue
A55: Jan | B55: 10960.79
A56: Feb | B56: 20042.99
A57: Mar | B57: 32201.91
A58: Apr | B58: 25296.13
A59: May | B59: 21629.24
A60: Jun | B60: 21702.69
A61: Grand Total | B61: 131833.75
A68: Q33 · Mix, not rupees. Start a PivotTable at A69. Show each region as a share of company revenue.
A70: Row Labels | B70: Sum of Revenue | C70: Sum of Revenue2
...

Sheet Data_Charts
A1: CHART PACK FOR INTERPRETATION (Q35–Q40)
A2: Four charts sit on this sheet. Underlying numbers are formula-driven from SalesData so they stay in sync. Do not delete the charts.
A4: Chart A source — Revenue by Region
A5: Region | B5: Revenue | C5: Share | D5: Orders | E5: Avg Order Value
A6: North | B6: =SUMIF(#REF!,A6,#REF!) -> #REF! | C6: =IF($B$10=0,0,B6/$B$10) -> #REF! | D6: =COUNTIF(#REF!,A6) -> #REF! | E6: =IF(D6=0,0,B6/D6) -> #REF!
A7: South | B7: =SUMIF(#REF!,A7,#REF!) -> #REF! | C7: =IF($B$10=0,0,B7/$B$10) -> #REF! | D7: =COUNTIF(#REF!,A7) -> #REF! | E7: =IF(D7=0,0,B7/D7) -> #REF!
A8: East | B8: =SUMIF(#REF!,A8,#REF!) -> #REF! | C8: =IF($B$10=0,0,B8/$B$10) -> #REF! | D8: =COUNTIF(#REF!,A8) -> #REF! | E8: =IF(D8=0,0,B8/D8) -> #REF!
A9: West | B9: =SUMIF(#REF!,A9,#REF!) -> #REF! | C9: =IF($B$10=0,0,B9/$B$10) -> #REF! | D9: =COUNTIF(#REF!,A9) -> #REF! | E9: =IF(D9=0,0,B9/D9) -> #REF!
A10: Total | B10: =SUM(B6:B9) -> #REF! | C10: =SUM(C6:C9) -> #REF! | D10: =SUM(D6:D9) -> #REF! | E10: =IF(D10=0,0,B10/D10) -> #REF!
A13: Chart B source — Monthly revenue by Channel
A14: Month | B14: Online | C14: Retail | D14: Wholesale | E14: Total
A15: Jan | B15: =SUMPRODUCT((MONTH(#REF!)=1)*(#REF!="Online")*(#REF!)) -> #REF! | C15: =SUMPRODUCT((MONTH(#REF!)=1)*(#REF!="Retail")*(#REF!)) -> #REF! | D15: =SUMPRODUCT((MONTH(#REF!)=1)*(#REF!="Wholesale")*(#REF!)) -> #REF! | E15: =SUM(B15:D15) -> #REF!
A16: Feb | B16: =SUMPRODUCT((MONTH(#REF!)=2)*(#REF!="Online")*(#REF!)) -> #REF! | C16: =SUMPRODUCT((MONTH(#REF!)=2)*(#REF!="Retail")*(#REF!)) -> #REF! | D16: =SUMPRODUCT((MONTH(#REF!)=2)*(#REF!="Wholesale")*(#REF!)) -> #REF! | E16: =SUM(B16:D16) -> #REF!
A17: Mar | B17: =SUMPRODUCT((MONTH(#REF!)=3)*(#REF!="Online")*(#REF!)) -> #REF! | C17: =SUMPRODUCT((MONTH(#REF!)=3)*(#REF!="Retail")*(#REF!)) -> #REF! | D17: =SUMPRODUCT((MONTH(#REF!)=3)*(#REF!="Wholesale")*(#REF!)) -> #REF! | E17: =SUM(B17:D17) -> #REF!
A18: Apr | B18: =SUMPRODUCT((MONTH(#REF!)=4)*(#REF!="Online")*(#REF!)) -> #REF! | C18: =SUMPRODUCT((MONTH(#REF!)=4)*(#REF!="Retail")*(#REF!)) -> #REF! | D18: =SUMPRODUCT((MONTH(#REF!)=4)*(#REF!="Wholesale")*(#REF!)) -> #REF! | E18: =SUM(B18:D18) -> #REF!
A19: May | B19: =SUMPRODUCT((MONTH(#REF!)=5)*(#REF!="Online")*(#REF!)) -> #REF! | C19: =SUMPRODUCT((MONTH(#REF!)=5)*(#REF!="Retail")*(#REF!)) -> #REF! | D19: =SUMPRODUCT((MONTH(#REF!)=5)*(#REF!="Wholesale")*(#REF!)) -> #REF! | E19: =SUM(B19:D19) -> #REF!
A20: Jun | B20: =SUMPRODUCT((MONTH(#REF!)=6)*(#REF!="Online")*(#REF!)) -> #REF! | C20: =SUMPRODUCT((MONTH(#REF!)=6)*(#REF!="Retail")*(#REF!)) -> #REF! | D20: =SUMPRODUCT((MONTH(#REF!)=6)*(#REF!="Wholesale")*(#REF!)) -> #REF! | E20: =SUM(B20:D20) -> #REF!
A21: Total | B21: =SUM(B15:B20) -> #REF! | C21: =SUM(C15:C20) -> #REF! | D21: =SUM(D15:D20) -> #REF! | E21: =SUM(E15:E20) -> #REF!
A24: Chart C source — Revenue by Category
A25: Category | B25: Revenue | C25: Share
A26: Electronics | B26: =SUMIF(#REF!,A26,#REF!) -> #REF! | C26: =IF($B$30=0,0,B26/$B$30) -> #REF!
A27: Furniture | B27: =SUMIF(#REF!,A27,#REF!) -> #REF! | C27: =IF($B$30=0,0,B27/$B$30) -> #REF!
A28: Office Supplies | B28: =SUMIF(#REF!,A28,#REF!) -> #REF! | C28: =IF($B$30=0,0,B28/$B$30) -> #REF!
A29: Apparel | B29: =SUMIF(#REF!,A29,#REF!) -> #REF! | C29: =IF($B$30=0,0,B29/$B$30) -> #REF!
A30: Total | B30: =SUM(B26:B29) -> #REF! | C30: =SUM(C26:C29) -> #REF!
A33: Chart D source — Revenue by Category × Channel
A34: Category | B34: Online | C34: Retail | D34: Wholesale
A35: Electronics | B35: =SUMIFS(#REF!,#REF!,A35,#REF!,"Online") -> #REF! | C35: =SUMIFS(#REF!,#REF!,A35,#REF!,"Retail") -> #REF! | D35: =SUMIFS(#REF!,#REF!,A35,#REF!,"Wholesale") -> #REF!
A36: Furniture | B36: =SUMIFS(#REF!,#REF!,A36,#REF!,"Online") -> #REF! | C36: =SUMIFS(#REF!,#REF!,A36,#REF!,"Retail") -> #REF! | D36: =SUMIFS(#REF!,#REF!,A36,#REF!,"Wholesale") -> #REF!
A37: Office Supplies | B37: =SUMIFS(#REF!,#REF!,A37,#REF!,"Online") -> #REF! | C37: =SUMIFS(#REF!,#REF!,A37,#REF!,"Retail") -> #REF! | D37: =SUMIFS(#REF!,#REF!,A37,#REF!,"Wholesale") -> #REF!
A38: Apparel | B38: =SUMIFS(#REF!,#REF!,A38,#REF!,"Online") -> #REF! | C38: =SUMIFS(#REF!,#REF!,A38,#REF!,"Retail") -> #REF! | D38: =SUMIFS(#REF!,#REF!,A38,#REF!,"Wholesale") -> #REF!
A41: Reference — SalesRep leaderboard (not charted; useful when checking Q31) | E41: Avg discount by Region
A42: SalesRep | B42: Revenue | C42: Orders | E42: Region | F42: Avg Discount
A43: Rahul Mehta | B43: =SUMIF(#REF!,A43,#REF!) -> #REF! | C43: =COUNTIF(#REF!,A43) -> #REF! | E43: North | F43: =AVERAGEIF(#REF!,E43,#REF!) -> #REF!
A44: Priya Sharma | B44: =SUMIF(#REF!,A44,#REF!) -> #REF! | C44: =COUNTIF(#REF!,A44) -> #REF! | E44: South | F44: =AVERAGEIF(#REF!,E44,#REF!) -> #REF!
A45: Vikram Patel | B45: =SUMIF(#REF!,A45,#REF!) -> #REF! | C45: =COUNTIF(#REF!,A45) -> #REF! | E45: East | F45: =AVERAGEIF(#REF!,E45,#REF!) -> #REF!
A46: Neha Reddy | B46: =SUMIF(#REF!,A46,#REF!) -> #REF! | C46: =COUNTIF(#REF!,A46) -> #REF! | E46: West | F46: =AVERAGEIF(#REF!,E46,#REF!) -> #REF!
A47: Arjun Nair | B47: =SUMIF(#REF!,A47,#REF!) -> #REF! | C47: =COUNTIF(#REF!,A47) -> #REF!
A48: Sofia Dsouza | B48: =SUMIF(#REF!,A48,#REF!) -> #REF! | C48: =COUNTIF(#REF!,A48) -> #REF!
A49: Karan Singh | B49: =SUMIF(#REF!,A49,#REF!) -> #REF! | C49: =COUNTIF(#REF!,A49) -> #REF!
...
